Traceback (most recent call last):
  File "/home/codespace/.cache/pypoetry/virtualenvs/vitals-fd2sur0F-py3.12/lib/python3.12/site-packages/jupyter_cache/executors/utils.py", line 58, in single_nb_execution
    executenb(
  File "/home/codespace/.cache/pypoetry/virtualenvs/vitals-fd2sur0F-py3.12/lib/python3.12/site-packages/nbclient/client.py", line 1314, in execute
    return NotebookClient(nb=nb, resources=resources, km=km, **kwargs).execute()
           ^^^^^^^^^^^^^^^^^^^^^^^^^^^^^^^^^^^^^^^^^^^^^^^^^^^^^^^^^^^^^^^^^^^^^
  File "/home/codespace/.cache/pypoetry/virtualenvs/vitals-fd2sur0F-py3.12/lib/python3.12/site-packages/jupyter_core/utils/__init__.py", line 165, in wrapped
    return loop.run_until_complete(inner)
           ^^^^^^^^^^^^^^^^^^^^^^^^^^^^^^
  File "/usr/local/python/3.12.1/lib/python3.12/asyncio/base_events.py", line 684, in run_until_complete
    return future.result()
           ^^^^^^^^^^^^^^^
  File "/home/codespace/.cache/pypoetry/virtualenvs/vitals-fd2sur0F-py3.12/lib/python3.12/site-packages/nbclient/client.py", line 709, in async_execute
    await self.async_execute_cell(
  File "/home/codespace/.cache/pypoetry/virtualenvs/vitals-fd2sur0F-py3.12/lib/python3.12/site-packages/nbclient/client.py", line 1062, in async_execute_cell
    await self._check_raise_for_error(cell, cell_index, exec_reply)
  File "/home/codespace/.cache/pypoetry/virtualenvs/vitals-fd2sur0F-py3.12/lib/python3.12/site-packages/nbclient/client.py", line 918, in _check_raise_for_error
    raise CellExecutionError.from_cell_and_msg(cell, exec_reply_content)
nbclient.exceptions.CellExecutionError: An error occurred while executing the following cell:
------------------
# Import required libraries
import os
import folium
import earthaccess
import warnings
import folium.plugins
import pandas as pd
import geopandas as gpd
import math

from branca.element import Figure
from IPython.display import display
from shapely import geometry
from skimage import io
from datetime import timedelta
from shapely.geometry.polygon import orient
from matplotlib import pyplot as plt
------------------


[0;31m---------------------------------------------------------------------------[0m
[0;31mModuleNotFoundError[0m                       Traceback (most recent call last)
Cell [0;32mIn[1], line 3[0m
[1;32m      1[0m [38;5;66;03m# Import required libraries[39;00m
[1;32m      2[0m [38;5;28;01mimport[39;00m [38;5;21;01mos[39;00m
[0;32m----> 3[0m [38;5;28;01mimport[39;00m [38;5;21;01mfolium[39;00m
[1;32m      4[0m [38;5;28;01mimport[39;00m [38;5;21;01mearthaccess[39;00m
[1;32m      5[0m [38;5;28;01mimport[39;00m [38;5;21;01mwarnings[39;00m

[0;31mModuleNotFoundError[0m: No module named 'folium'

